25Not Found: /favicon.ico
Too Many Requests: /login/
Internal Server Error: /mgt-dashboard/
Traceback (most recent call last):
  File "C:\Users\deedadey\AppData\Local\Programs\Python\Python312\Lib\site-packages\django\core\handlers\exception.py", line 55, in inner
    response = get_response(request)
               ^^^^^^^^^^^^^^^^^^^^^
  File "C:\Users\deedadey\AppData\Local\Programs\Python\Python312\Lib\site-packages\django\core\handlers\base.py", line 197, in _get_response
    response = wrapped_callback(request, *callback_args, **callback_kwargs)
               ^^^^^^^^^^^^^^^^^^^^^^^^^^^^^^^^^^^^^^^^^^^^^^^^^^^^^^^^^^^^
  File "C:\Users\deedadey\AppData\Local\Programs\Python\Python312\Lib\site-packages\django\contrib\auth\decorators.py", line 60, in _view_wrapper
    return view_func(request, *args, **kwargs)
           ^^^^^^^^^^^^^^^^^^^^^^^^^^^^^^^^^^^
  File "C:\Users\deedadey\AppData\Local\Programs\Python\Python312\Lib\site-packages\django\contrib\auth\decorators.py", line 60, in _view_wrapper
    return view_func(request, *args, **kwargs)
           ^^^^^^^^^^^^^^^^^^^^^^^^^^^^^^^^^^^
  File "C:\Users\deedadey\PycharmProjects\FWB\fwb\contributions\views.py", line 333, in manager_dashboard
    return render(request, "contributions/manager_dashboard.html", {
           ^^^^^^^^^^^^^^^^^^^^^^^^^^^^^^^^^^^^^^^^^^^^^^^^^^^^^^^^^
  File "C:\Users\deedadey\AppData\Local\Programs\Python\Python312\Lib\site-packages\django\shortcuts.py", line 25, in render
    content = loader.render_to_string(template_name, context, request, using=using)
              ^^^^^^^^^^^^^^^^^^^^^^^^^^^^^^^^^^^^^^^^^^^^^^^^^^^^^^^^^^^^^^^^^^^^^
  File "C:\Users\deedadey\AppData\Local\Programs\Python\Python312\Lib\site-packages\django\template\loader.py", line 62, in render_to_string
    return template.render(context, request)
           ^^^^^^^^^^^^^^^^^^^^^^^^^^^^^^^^^
  File "C:\Users\deedadey\AppData\Local\Programs\Python\Python312\Lib\site-packages\django\template\backends\django.py", line 107, in render
    return self.template.render(context)
           ^^^^^^^^^^^^^^^^^^^^^^^^^^^^^
  File "C:\Users\deedadey\AppData\Local\Programs\Python\Python312\Lib\site-packages\django\template\base.py", line 171, in render
    return self._render(context)
           ^^^^^^^^^^^^^^^^^^^^^
  File "C:\Users\deedadey\AppData\Local\Programs\Python\Python312\Lib\site-packages\django\template\base.py", line 163, in _render
    return self.nodelist.render(context)
           ^^^^^^^^^^^^^^^^^^^^^^^^^^^^^
  File "C:\Users\deedadey\AppData\Local\Programs\Python\Python312\Lib\site-packages\django\template\base.py", line 1008, in render
    return SafeString("".join([node.render_annotated(context) for node in self]))
                               ^^^^^^^^^^^^^^^^^^^^^^^^^^^^^^
  File "C:\Users\deedadey\AppData\Local\Programs\Python\Python312\Lib\site-packages\django\template\base.py", line 969, in render_annotated
    return self.render(context)
           ^^^^^^^^^^^^^^^^^^^^
  File "C:\Users\deedadey\AppData\Local\Programs\Python\Python312\Lib\site-packages\django\template\loader_tags.py", line 159, in render
    return compiled_parent._render(context)
           ^^^^^^^^^^^^^^^^^^^^^^^^^^^^^^^^
  File "C:\Users\deedadey\AppData\Local\Programs\Python\Python312\Lib\site-packages\django\template\base.py", line 163, in _render
    return self.nodelist.render(context)
           ^^^^^^^^^^^^^^^^^^^^^^^^^^^^^
  File "C:\Users\deedadey\AppData\Local\Programs\Python\Python312\Lib\site-packages\django\template\base.py", line 1008, in render
    return SafeString("".join([node.render_annotated(context) for node in self]))
                               ^^^^^^^^^^^^^^^^^^^^^^^^^^^^^^
  File "C:\Users\deedadey\AppData\Local\Programs\Python\Python312\Lib\site-packages\django\template\base.py", line 969, in render_annotated
    return self.render(context)
           ^^^^^^^^^^^^^^^^^^^^
  File "C:\Users\deedadey\AppData\Local\Programs\Python\Python312\Lib\site-packages\django\template\loader_tags.py", line 65, in render
    result = block.nodelist.render(context)
             ^^^^^^^^^^^^^^^^^^^^^^^^^^^^^^
  File "C:\Users\deedadey\AppData\Local\Programs\Python\Python312\Lib\site-packages\django\template\base.py", line 1008, in render
    return SafeString("".join([node.render_annotated(context) for node in self]))
                               ^^^^^^^^^^^^^^^^^^^^^^^^^^^^^^
  File "C:\Users\deedadey\AppData\Local\Programs\Python\Python312\Lib\site-packages\django\template\base.py", line 969, in render_annotated
    return self.render(context)
           ^^^^^^^^^^^^^^^^^^^^
  File "C:\Users\deedadey\AppData\Local\Programs\Python\Python312\Lib\site-packages\django\template\defaulttags.py", line 480, in render
    url = reverse(view_name, args=args, kwargs=kwargs, current_app=current_app)
          ^^^^^^^^^^^^^^^^^^^^^^^^^^^^^^^^^^^^^^^^^^^^^^^^^^^^^^^^^^^^^^^^^^^^^
  File "C:\Users\deedadey\AppData\Local\Programs\Python\Python312\Lib\site-packages\django\urls\base.py", line 88, in reverse
    return resolver._reverse_with_prefix(view, prefix, *args, **kwargs)
           ^^^^^^^^^^^^^^^^^^^^^^^^^^^^^^^^^^^^^^^^^^^^^^^^^^^^^^^^^^^^
  File "C:\Users\deedadey\AppData\Local\Programs\Python\Python312\Lib\site-packages\django\urls\resolvers.py", line 831, in _reverse_with_prefix
    raise NoReverseMatch(msg)
django.urls.exceptions.NoReverseMatch: Reverse for 'send_reminder_message' not found. 'send_reminder_message' is not a valid view function or pattern name.
Internal Server Error: /mgt-dashboard/
Traceback (most recent call last):
  File "C:\Users\deedadey\AppData\Local\Programs\Python\Python312\Lib\site-packages\django\core\handlers\exception.py", line 55, in inner
    response = get_response(request)
               ^^^^^^^^^^^^^^^^^^^^^
  File "C:\Users\deedadey\AppData\Local\Programs\Python\Python312\Lib\site-packages\django\core\handlers\base.py", line 197, in _get_response
    response = wrapped_callback(request, *callback_args, **callback_kwargs)
               ^^^^^^^^^^^^^^^^^^^^^^^^^^^^^^^^^^^^^^^^^^^^^^^^^^^^^^^^^^^^
  File "C:\Users\deedadey\AppData\Local\Programs\Python\Python312\Lib\site-packages\django\contrib\auth\decorators.py", line 60, in _view_wrapper
    return view_func(request, *args, **kwargs)
           ^^^^^^^^^^^^^^^^^^^^^^^^^^^^^^^^^^^
  File "C:\Users\deedadey\AppData\Local\Programs\Python\Python312\Lib\site-packages\django\contrib\auth\decorators.py", line 60, in _view_wrapper
    return view_func(request, *args, **kwargs)
           ^^^^^^^^^^^^^^^^^^^^^^^^^^^^^^^^^^^
  File "C:\Users\deedadey\PycharmProjects\FWB\fwb\contributions\views.py", line 333, in manager_dashboard
    return render(request, "contributions/manager_dashboard.html", {
           ^^^^^^^^^^^^^^^^^^^^^^^^^^^^^^^^^^^^^^^^^^^^^^^^^^^^^^^^^
  File "C:\Users\deedadey\AppData\Local\Programs\Python\Python312\Lib\site-packages\django\shortcuts.py", line 25, in render
    content = loader.render_to_string(template_name, context, request, using=using)
              ^^^^^^^^^^^^^^^^^^^^^^^^^^^^^^^^^^^^^^^^^^^^^^^^^^^^^^^^^^^^^^^^^^^^^
  File "C:\Users\deedadey\AppData\Local\Programs\Python\Python312\Lib\site-packages\django\template\loader.py", line 62, in render_to_string
    return template.render(context, request)
           ^^^^^^^^^^^^^^^^^^^^^^^^^^^^^^^^^
  File "C:\Users\deedadey\AppData\Local\Programs\Python\Python312\Lib\site-packages\django\template\backends\django.py", line 107, in render
    return self.template.render(context)
           ^^^^^^^^^^^^^^^^^^^^^^^^^^^^^
  File "C:\Users\deedadey\AppData\Local\Programs\Python\Python312\Lib\site-packages\django\template\base.py", line 171, in render
    return self._render(context)
           ^^^^^^^^^^^^^^^^^^^^^
  File "C:\Users\deedadey\AppData\Local\Programs\Python\Python312\Lib\site-packages\django\template\base.py", line 163, in _render
    return self.nodelist.render(context)
           ^^^^^^^^^^^^^^^^^^^^^^^^^^^^^
  File "C:\Users\deedadey\AppData\Local\Programs\Python\Python312\Lib\site-packages\django\template\base.py", line 1008, in render
    return SafeString("".join([node.render_annotated(context) for node in self]))
                               ^^^^^^^^^^^^^^^^^^^^^^^^^^^^^^
  File "C:\Users\deedadey\AppData\Local\Programs\Python\Python312\Lib\site-packages\django\template\base.py", line 969, in render_annotated
    return self.render(context)
           ^^^^^^^^^^^^^^^^^^^^
  File "C:\Users\deedadey\AppData\Local\Programs\Python\Python312\Lib\site-packages\django\template\loader_tags.py", line 159, in render
    return compiled_parent._render(context)
           ^^^^^^^^^^^^^^^^^^^^^^^^^^^^^^^^
  File "C:\Users\deedadey\AppData\Local\Programs\Python\Python312\Lib\site-packages\django\template\base.py", line 163, in _render
    return self.nodelist.render(context)
           ^^^^^^^^^^^^^^^^^^^^^^^^^^^^^
  File "C:\Users\deedadey\AppData\Local\Programs\Python\Python312\Lib\site-packages\django\template\base.py", line 1008, in render
    return SafeString("".join([node.render_annotated(context) for node in self]))
                               ^^^^^^^^^^^^^^^^^^^^^^^^^^^^^^
  File "C:\Users\deedadey\AppData\Local\Programs\Python\Python312\Lib\site-packages\django\template\base.py", line 969, in render_annotated
    return self.render(context)
           ^^^^^^^^^^^^^^^^^^^^
  File "C:\Users\deedadey\AppData\Local\Programs\Python\Python312\Lib\site-packages\django\template\loader_tags.py", line 65, in render
    result = block.nodelist.render(context)
             ^^^^^^^^^^^^^^^^^^^^^^^^^^^^^^
  File "C:\Users\deedadey\AppData\Local\Programs\Python\Python312\Lib\site-packages\django\template\base.py", line 1008, in render
    return SafeString("".join([node.render_annotated(context) for node in self]))
                               ^^^^^^^^^^^^^^^^^^^^^^^^^^^^^^
  File "C:\Users\deedadey\AppData\Local\Programs\Python\Python312\Lib\site-packages\django\template\base.py", line 969, in render_annotated
    return self.render(context)
           ^^^^^^^^^^^^^^^^^^^^
  File "C:\Users\deedadey\AppData\Local\Programs\Python\Python312\Lib\site-packages\django\template\defaulttags.py", line 480, in render
    url = reverse(view_name, args=args, kwargs=kwargs, current_app=current_app)
          ^^^^^^^^^^^^^^^^^^^^^^^^^^^^^^^^^^^^^^^^^^^^^^^^^^^^^^^^^^^^^^^^^^^^^
  File "C:\Users\deedadey\AppData\Local\Programs\Python\Python312\Lib\site-packages\django\urls\base.py", line 88, in reverse
    return resolver._reverse_with_prefix(view, prefix, *args, **kwargs)
           ^^^^^^^^^^^^^^^^^^^^^^^^^^^^^^^^^^^^^^^^^^^^^^^^^^^^^^^^^^^^
  File "C:\Users\deedadey\AppData\Local\Programs\Python\Python312\Lib\site-packages\django\urls\resolvers.py", line 831, in _reverse_with_prefix
    raise NoReverseMatch(msg)
django.urls.exceptions.NoReverseMatch: Reverse for 'send_reminder_message' not found. 'send_reminder_message' is not a valid view function or pattern name.
Not Found: /favicon.ico
Not Found: /favicon.ico
Not Found: /accounts/login/
Not Found: /accounts/login/
Not Found: /accounts/login/
Not Found: /favicon.ico
Not Found: /accounts/login/
Not Found: /accounts/login/
Internal Server Error: /mgt-dashboard/
Traceback (most recent call last):
  File "C:\Users\deedadey\AppData\Local\Programs\Python\Python312\Lib\site-packages\django\core\handlers\exception.py", line 55, in inner
    response = get_response(request)
               ^^^^^^^^^^^^^^^^^^^^^
  File "C:\Users\deedadey\AppData\Local\Programs\Python\Python312\Lib\site-packages\django\core\handlers\base.py", line 197, in _get_response
    response = wrapped_callback(request, *callback_args, **callback_kwargs)
               ^^^^^^^^^^^^^^^^^^^^^^^^^^^^^^^^^^^^^^^^^^^^^^^^^^^^^^^^^^^^
  File "C:\Users\deedadey\AppData\Local\Programs\Python\Python312\Lib\site-packages\django\contrib\auth\decorators.py", line 60, in _view_wrapper
    return view_func(request, *args, **kwargs)
           ^^^^^^^^^^^^^^^^^^^^^^^^^^^^^^^^^^^
  File "C:\Users\deedadey\AppData\Local\Programs\Python\Python312\Lib\site-packages\django\contrib\auth\decorators.py", line 60, in _view_wrapper
    return view_func(request, *args, **kwargs)
           ^^^^^^^^^^^^^^^^^^^^^^^^^^^^^^^^^^^
  File "C:\Users\deedadey\PycharmProjects\FWB\fwb\contributions\views.py", line 477, in manager_dashboard
    "filter_option": filter_option,
                     ^^^^^^^^^^^^^
NameError: name 'filter_option' is not defined
Not Found: /favicon.ico
Not Found: /favicon.ico
Not Found: /favicon.ico
Not Found: /favicon.ico
Not Found: /accounts/login/
Not Found: /accounts/login/
Not Found: /accounts/login/
Internal Server Error: /mgt-dashboard/
Traceback (most recent call last):
  File "C:\Users\IT MINISTRY\PycharmProjects\FWB\.venv\Lib\site-packages\django\core\handlers\exception.py", line 55, in inner
    response = get_response(request)
  File "C:\Users\IT MINISTRY\PycharmProjects\FWB\.venv\Lib\site-packages\django\core\handlers\base.py", line 197, in _get_response
    response = wrapped_callback(request, *callback_args, **callback_kwargs)
  File "C:\Users\IT MINISTRY\PycharmProjects\FWB\.venv\Lib\site-packages\django\contrib\auth\decorators.py", line 60, in _view_wrapper
    return view_func(request, *args, **kwargs)
  File "C:\Users\IT MINISTRY\PycharmProjects\FWB\.venv\Lib\site-packages\django\contrib\auth\decorators.py", line 60, in _view_wrapper
    return view_func(request, *args, **kwargs)
  File "C:\Users\IT MINISTRY\PycharmProjects\FWB\fwb\contributions\views.py", line 485, in manager_dashboard
    send_mail(
    ~~~~~~~~~^
        subject,
        ^^^^^^^^
    ...<3 lines>...
        fail_silently=False,
        ^^^^^^^^^^^^^^^^^^^^
    )
    ^
  File "C:\Users\IT MINISTRY\PycharmProjects\FWB\.venv\Lib\site-packages\django\core\mail\__init__.py", line 88, in send_mail
    return mail.send()
           ~~~~~~~~~^^
  File "C:\Users\IT MINISTRY\PycharmProjects\FWB\.venv\Lib\site-packages\django\core\mail\message.py", line 301, in send
    return self.get_connection(fail_silently).send_messages([self])
           ~~~~~~~~~~~~~~~~~~~~~~~~~~~~~~~~~~~~~~~~~~~~~~~~^^^^^^^^
  File "C:\Users\IT MINISTRY\PycharmProjects\FWB\.venv\Lib\site-packages\django\core\mail\backends\smtp.py", line 128, in send_messages
    new_conn_created = self.open()
  File "C:\Users\IT MINISTRY\PycharmProjects\FWB\.venv\Lib\site-packages\django\core\mail\backends\smtp.py", line 93, in open
    self.connection.starttls(context=self.ssl_context)
    ~~~~~~~~~~~~~~~~~~~~~~~~^^^^^^^^^^^^^^^^^^^^^^^^^^
  File "C:\Python313\Lib\smtplib.py", line 769, in starttls
    self.ehlo_or_helo_if_needed()
    ~~~~~~~~~~~~~~~~~~~~~~~~~~~^^
  File "C:\Python313\Lib\smtplib.py", line 611, in ehlo_or_helo_if_needed
    if not (200 <= self.ehlo()[0] <= 299):
                   ~~~~~~~~~^^
  File "C:\Python313\Lib\smtplib.py", line 451, in ehlo
    self.putcmd(self.ehlo_msg, name or self.local_hostname)
    ~~~~~~~~~~~^^^^^^^^^^^^^^^^^^^^^^^^^^^^^^^^^^^^^^^^^^^^
  File "C:\Python313\Lib\smtplib.py", line 378, in putcmd
    self.send(f'{s}{CRLF}')
    ~~~~~~~~~^^^^^^^^^^^^^^
  File "C:\Python313\Lib\smtplib.py", line 365, in send
    raise SMTPServerDisconnected('please run connect() first')
smtplib.SMTPServerDisconnected: please run connect() first
Not Found: /accounts/login/
Not Found: /favicon.ico
Internal Server Error: /mgt-dashboard/
Traceback (most recent call last):
  File "C:\Users\IT MINISTRY\PycharmProjects\FWB\.venv\Lib\site-packages\django\core\handlers\exception.py", line 55, in inner
    response = get_response(request)
  File "C:\Users\IT MINISTRY\PycharmProjects\FWB\.venv\Lib\site-packages\django\core\handlers\base.py", line 197, in _get_response
    response = wrapped_callback(request, *callback_args, **callback_kwargs)
  File "C:\Users\IT MINISTRY\PycharmProjects\FWB\.venv\Lib\site-packages\django\contrib\auth\decorators.py", line 60, in _view_wrapper
    return view_func(request, *args, **kwargs)
  File "C:\Users\IT MINISTRY\PycharmProjects\FWB\.venv\Lib\site-packages\django\contrib\auth\decorators.py", line 60, in _view_wrapper
    return view_func(request, *args, **kwargs)
  File "C:\Users\IT MINISTRY\PycharmProjects\FWB\fwb\contributions\views.py", line 485, in manager_dashboard
    send_mail(
    ~~~~~~~~~^
        subject,
        ^^^^^^^^
    ...<3 lines>...
        fail_silently=False,
        ^^^^^^^^^^^^^^^^^^^^
    )
    ^
  File "C:\Users\IT MINISTRY\PycharmProjects\FWB\.venv\Lib\site-packages\django\core\mail\__init__.py", line 88, in send_mail
    return mail.send()
           ~~~~~~~~~^^
  File "C:\Users\IT MINISTRY\PycharmProjects\FWB\.venv\Lib\site-packages\django\core\mail\message.py", line 301, in send
    return self.get_connection(fail_silently).send_messages([self])
           ~~~~~~~~~~~~~~~~~~~~~~~~~~~~~~~~~~~~~~~~~~~~~~~~^^^^^^^^
  File "C:\Users\IT MINISTRY\PycharmProjects\FWB\.venv\Lib\site-packages\django\core\mail\backends\smtp.py", line 128, in send_messages
    new_conn_created = self.open()
  File "C:\Users\IT MINISTRY\PycharmProjects\FWB\.venv\Lib\site-packages\django\core\mail\backends\smtp.py", line 93, in open
    self.connection.starttls(context=self.ssl_context)
    ~~~~~~~~~~~~~~~~~~~~~~~~^^^^^^^^^^^^^^^^^^^^^^^^^^
  File "C:\Python313\Lib\smtplib.py", line 769, in starttls
    self.ehlo_or_helo_if_needed()
    ~~~~~~~~~~~~~~~~~~~~~~~~~~~^^
  File "C:\Python313\Lib\smtplib.py", line 611, in ehlo_or_helo_if_needed
    if not (200 <= self.ehlo()[0] <= 299):
                   ~~~~~~~~~^^
  File "C:\Python313\Lib\smtplib.py", line 451, in ehlo
    self.putcmd(self.ehlo_msg, name or self.local_hostname)
    ~~~~~~~~~~~^^^^^^^^^^^^^^^^^^^^^^^^^^^^^^^^^^^^^^^^^^^^
  File "C:\Python313\Lib\smtplib.py", line 378, in putcmd
    self.send(f'{s}{CRLF}')
    ~~~~~~~~~^^^^^^^^^^^^^^
  File "C:\Python313\Lib\smtplib.py", line 365, in send
    raise SMTPServerDisconnected('please run connect() first')
smtplib.SMTPServerDisconnected: please run connect() first
Internal Server Error: /mgt-dashboard/
Traceback (most recent call last):
  File "C:\Users\IT MINISTRY\PycharmProjects\FWB\.venv\Lib\site-packages\django\core\handlers\exception.py", line 55, in inner
    response = get_response(request)
  File "C:\Users\IT MINISTRY\PycharmProjects\FWB\.venv\Lib\site-packages\django\core\handlers\base.py", line 197, in _get_response
    response = wrapped_callback(request, *callback_args, **callback_kwargs)
  File "C:\Users\IT MINISTRY\PycharmProjects\FWB\.venv\Lib\site-packages\django\contrib\auth\decorators.py", line 60, in _view_wrapper
    return view_func(request, *args, **kwargs)
  File "C:\Users\IT MINISTRY\PycharmProjects\FWB\.venv\Lib\site-packages\django\contrib\auth\decorators.py", line 60, in _view_wrapper
    return view_func(request, *args, **kwargs)
  File "C:\Users\IT MINISTRY\PycharmProjects\FWB\fwb\contributions\views.py", line 481, in manager_dashboard
    connection = get_connection()
                 ^^^^^^^^^^^^^^
NameError: name 'get_connection' is not defined
Internal Server Error: /mgt-dashboard/
Traceback (most recent call last):
  File "C:\Users\IT MINISTRY\PycharmProjects\FWB\.venv\Lib\site-packages\django\core\handlers\exception.py", line 55, in inner
    response = get_response(request)
  File "C:\Users\IT MINISTRY\PycharmProjects\FWB\.venv\Lib\site-packages\django\core\handlers\base.py", line 197, in _get_response
    response = wrapped_callback(request, *callback_args, **callback_kwargs)
  File "C:\Users\IT MINISTRY\PycharmProjects\FWB\.venv\Lib\site-packages\django\contrib\auth\decorators.py", line 60, in _view_wrapper
    return view_func(request, *args, **kwargs)
  File "C:\Users\IT MINISTRY\PycharmProjects\FWB\.venv\Lib\site-packages\django\contrib\auth\decorators.py", line 60, in _view_wrapper
    return view_func(request, *args, **kwargs)
  File "C:\Users\IT MINISTRY\PycharmProjects\FWB\fwb\contributions\views.py", line 482, in manager_dashboard
    connection.open()
    ~~~~~~~~~~~~~~~^^
  File "C:\Users\IT MINISTRY\PycharmProjects\FWB\.venv\Lib\site-packages\django\core\mail\backends\smtp.py", line 93, in open
    self.connection.starttls(context=self.ssl_context)
    ~~~~~~~~~~~~~~~~~~~~~~~~^^^^^^^^^^^^^^^^^^^^^^^^^^
  File "C:\Python313\Lib\smtplib.py", line 769, in starttls
    self.ehlo_or_helo_if_needed()
    ~~~~~~~~~~~~~~~~~~~~~~~~~~~^^
  File "C:\Python313\Lib\smtplib.py", line 611, in ehlo_or_helo_if_needed
    if not (200 <= self.ehlo()[0] <= 299):
                   ~~~~~~~~~^^
  File "C:\Python313\Lib\smtplib.py", line 451, in ehlo
    self.putcmd(self.ehlo_msg, name or self.local_hostname)
    ~~~~~~~~~~~^^^^^^^^^^^^^^^^^^^^^^^^^^^^^^^^^^^^^^^^^^^^
  File "C:\Python313\Lib\smtplib.py", line 378, in putcmd
    self.send(f'{s}{CRLF}')
    ~~~~~~~~~^^^^^^^^^^^^^^
  File "C:\Python313\Lib\smtplib.py", line 365, in send
    raise SMTPServerDisconnected('please run connect() first')
smtplib.SMTPServerDisconnected: please run connect() first
Internal Server Error: /mgt-dashboard/
Traceback (most recent call last):
  File "C:\Users\IT MINISTRY\PycharmProjects\FWB\.venv\Lib\site-packages\django\core\handlers\exception.py", line 55, in inner
    response = get_response(request)
  File "C:\Users\IT MINISTRY\PycharmProjects\FWB\.venv\Lib\site-packages\django\core\handlers\base.py", line 197, in _get_response
    response = wrapped_callback(request, *callback_args, **callback_kwargs)
  File "C:\Users\IT MINISTRY\PycharmProjects\FWB\.venv\Lib\site-packages\django\contrib\auth\decorators.py", line 60, in _view_wrapper
    return view_func(request, *args, **kwargs)
  File "C:\Users\IT MINISTRY\PycharmProjects\FWB\.venv\Lib\site-packages\django\contrib\auth\decorators.py", line 60, in _view_wrapper
    return view_func(request, *args, **kwargs)
  File "C:\Users\IT MINISTRY\PycharmProjects\FWB\fwb\contributions\views.py", line 482, in manager_dashboard
    connection.open()
    ~~~~~~~~~~~~~~~^^
  File "C:\Users\IT MINISTRY\PycharmProjects\FWB\.venv\Lib\site-packages\django\core\mail\backends\smtp.py", line 93, in open
    self.connection.starttls(context=self.ssl_context)
    ~~~~~~~~~~~~~~~~~~~~~~~~^^^^^^^^^^^^^^^^^^^^^^^^^^
  File "C:\Python313\Lib\smtplib.py", line 769, in starttls
    self.ehlo_or_helo_if_needed()
    ~~~~~~~~~~~~~~~~~~~~~~~~~~~^^
  File "C:\Python313\Lib\smtplib.py", line 611, in ehlo_or_helo_if_needed
    if not (200 <= self.ehlo()[0] <= 299):
                   ~~~~~~~~~^^
  File "C:\Python313\Lib\smtplib.py", line 451, in ehlo
    self.putcmd(self.ehlo_msg, name or self.local_hostname)
    ~~~~~~~~~~~^^^^^^^^^^^^^^^^^^^^^^^^^^^^^^^^^^^^^^^^^^^^
  File "C:\Python313\Lib\smtplib.py", line 378, in putcmd
    self.send(f'{s}{CRLF}')
    ~~~~~~~~~^^^^^^^^^^^^^^
  File "C:\Python313\Lib\smtplib.py", line 365, in send
    raise SMTPServerDisconnected('please run connect() first')
smtplib.SMTPServerDisconnected: please run connect() first
Not Found: /favicon.ico
Internal Server Error: /mgt-dashboard/
Traceback (most recent call last):
  File "C:\Users\IT MINISTRY\PycharmProjects\FWB\.venv\Lib\site-packages\django\core\handlers\exception.py", line 55, in inner
    response = get_response(request)
  File "C:\Users\IT MINISTRY\PycharmProjects\FWB\.venv\Lib\site-packages\django\core\handlers\base.py", line 197, in _get_response
    response = wrapped_callback(request, *callback_args, **callback_kwargs)
  File "C:\Users\IT MINISTRY\PycharmProjects\FWB\.venv\Lib\site-packages\django\contrib\auth\decorators.py", line 60, in _view_wrapper
    return view_func(request, *args, **kwargs)
  File "C:\Users\IT MINISTRY\PycharmProjects\FWB\.venv\Lib\site-packages\django\contrib\auth\decorators.py", line 60, in _view_wrapper
    return view_func(request, *args, **kwargs)
  File "C:\Users\IT MINISTRY\PycharmProjects\FWB\fwb\contributions\views.py", line 482, in manager_dashboard
    connection.open()
    ~~~~~~~~~~~~~~~^^
  File "C:\Users\IT MINISTRY\PycharmProjects\FWB\.venv\Lib\site-packages\django\core\mail\backends\smtp.py", line 93, in open
    self.connection.starttls(context=self.ssl_context)
    ~~~~~~~~~~~~~~~~~~~~~~~~^^^^^^^^^^^^^^^^^^^^^^^^^^
  File "C:\Python313\Lib\smtplib.py", line 769, in starttls
    self.ehlo_or_helo_if_needed()
    ~~~~~~~~~~~~~~~~~~~~~~~~~~~^^
  File "C:\Python313\Lib\smtplib.py", line 611, in ehlo_or_helo_if_needed
    if not (200 <= self.ehlo()[0] <= 299):
                   ~~~~~~~~~^^
  File "C:\Python313\Lib\smtplib.py", line 451, in ehlo
    self.putcmd(self.ehlo_msg, name or self.local_hostname)
    ~~~~~~~~~~~^^^^^^^^^^^^^^^^^^^^^^^^^^^^^^^^^^^^^^^^^^^^
  File "C:\Python313\Lib\smtplib.py", line 378, in putcmd
    self.send(f'{s}{CRLF}')
    ~~~~~~~~~^^^^^^^^^^^^^^
  File "C:\Python313\Lib\smtplib.py", line 365, in send
    raise SMTPServerDisconnected('please run connect() first')
smtplib.SMTPServerDisconnected: please run connect() first
Not Found: /accounts/login/
Not Found: /accounts/login/
Not Found: /admin
Not Found: /favicon.ico
Internal Server Error: /mgt-dashboard/
Traceback (most recent call last):
  File "C:\Users\deedadey\AppData\Local\Programs\Python\Python312\Lib\site-packages\django\core\handlers\exception.py", line 55, in inner
    response = get_response(request)
               ^^^^^^^^^^^^^^^^^^^^^
  File "C:\Users\deedadey\AppData\Local\Programs\Python\Python312\Lib\site-packages\django\core\handlers\base.py", line 197, in _get_response
    response = wrapped_callback(request, *callback_args, **callback_kwargs)
               ^^^^^^^^^^^^^^^^^^^^^^^^^^^^^^^^^^^^^^^^^^^^^^^^^^^^^^^^^^^^
  File "C:\Users\deedadey\AppData\Local\Programs\Python\Python312\Lib\site-packages\django\contrib\auth\decorators.py", line 60, in _view_wrapper
    return view_func(request, *args, **kwargs)
           ^^^^^^^^^^^^^^^^^^^^^^^^^^^^^^^^^^^
  File "C:\Users\deedadey\AppData\Local\Programs\Python\Python312\Lib\site-packages\django\contrib\auth\decorators.py", line 60, in _view_wrapper
    return view_func(request, *args, **kwargs)
           ^^^^^^^^^^^^^^^^^^^^^^^^^^^^^^^^^^^
  File "C:\Users\deedadey\PycharmProjects\FWB\fwb\contributions\views.py", line 307, in manager_dashboard
    return render(request, "contributions/manager_dashboard.html", {
           ^^^^^^^^^^^^^^^^^^^^^^^^^^^^^^^^^^^^^^^^^^^^^^^^^^^^^^^^^
  File "C:\Users\deedadey\AppData\Local\Programs\Python\Python312\Lib\site-packages\django\shortcuts.py", line 25, in render
    content = loader.render_to_string(template_name, context, request, using=using)
              ^^^^^^^^^^^^^^^^^^^^^^^^^^^^^^^^^^^^^^^^^^^^^^^^^^^^^^^^^^^^^^^^^^^^^
  File "C:\Users\deedadey\AppData\Local\Programs\Python\Python312\Lib\site-packages\django\template\loader.py", line 62, in render_to_string
    return template.render(context, request)
           ^^^^^^^^^^^^^^^^^^^^^^^^^^^^^^^^^
  File "C:\Users\deedadey\AppData\Local\Programs\Python\Python312\Lib\site-packages\django\template\backends\django.py", line 107, in render
    return self.template.render(context)
           ^^^^^^^^^^^^^^^^^^^^^^^^^^^^^
  File "C:\Users\deedadey\AppData\Local\Programs\Python\Python312\Lib\site-packages\django\template\base.py", line 171, in render
    return self._render(context)
           ^^^^^^^^^^^^^^^^^^^^^
  File "C:\Users\deedadey\AppData\Local\Programs\Python\Python312\Lib\site-packages\django\template\base.py", line 163, in _render
    return self.nodelist.render(context)
           ^^^^^^^^^^^^^^^^^^^^^^^^^^^^^
  File "C:\Users\deedadey\AppData\Local\Programs\Python\Python312\Lib\site-packages\django\template\base.py", line 1008, in render
    return SafeString("".join([node.render_annotated(context) for node in self]))
                               ^^^^^^^^^^^^^^^^^^^^^^^^^^^^^^
  File "C:\Users\deedadey\AppData\Local\Programs\Python\Python312\Lib\site-packages\django\template\base.py", line 969, in render_annotated
    return self.render(context)
           ^^^^^^^^^^^^^^^^^^^^
  File "C:\Users\deedadey\AppData\Local\Programs\Python\Python312\Lib\site-packages\django\template\loader_tags.py", line 159, in render
    return compiled_parent._render(context)
           ^^^^^^^^^^^^^^^^^^^^^^^^^^^^^^^^
  File "C:\Users\deedadey\AppData\Local\Programs\Python\Python312\Lib\site-packages\django\template\base.py", line 163, in _render
    return self.nodelist.render(context)
           ^^^^^^^^^^^^^^^^^^^^^^^^^^^^^
  File "C:\Users\deedadey\AppData\Local\Programs\Python\Python312\Lib\site-packages\django\template\base.py", line 1008, in render
    return SafeString("".join([node.render_annotated(context) for node in self]))
                               ^^^^^^^^^^^^^^^^^^^^^^^^^^^^^^
  File "C:\Users\deedadey\AppData\Local\Programs\Python\Python312\Lib\site-packages\django\template\base.py", line 969, in render_annotated
    return self.render(context)
           ^^^^^^^^^^^^^^^^^^^^
  File "C:\Users\deedadey\AppData\Local\Programs\Python\Python312\Lib\site-packages\django\template\loader_tags.py", line 65, in render
    result = block.nodelist.render(context)
             ^^^^^^^^^^^^^^^^^^^^^^^^^^^^^^
  File "C:\Users\deedadey\AppData\Local\Programs\Python\Python312\Lib\site-packages\django\template\base.py", line 1008, in render
    return SafeString("".join([node.render_annotated(context) for node in self]))
                               ^^^^^^^^^^^^^^^^^^^^^^^^^^^^^^
  File "C:\Users\deedadey\AppData\Local\Programs\Python\Python312\Lib\site-packages\django\template\base.py", line 969, in render_annotated
    return self.render(context)
           ^^^^^^^^^^^^^^^^^^^^
  File "C:\Users\deedadey\AppData\Local\Programs\Python\Python312\Lib\site-packages\django\template\defaulttags.py", line 480, in render
    url = reverse(view_name, args=args, kwargs=kwargs, current_app=current_app)
          ^^^^^^^^^^^^^^^^^^^^^^^^^^^^^^^^^^^^^^^^^^^^^^^^^^^^^^^^^^^^^^^^^^^^^
  File "C:\Users\deedadey\AppData\Local\Programs\Python\Python312\Lib\site-packages\django\urls\base.py", line 88, in reverse
    return resolver._reverse_with_prefix(view, prefix, *args, **kwargs)
           ^^^^^^^^^^^^^^^^^^^^^^^^^^^^^^^^^^^^^^^^^^^^^^^^^^^^^^^^^^^^
  File "C:\Users\deedadey\AppData\Local\Programs\Python\Python312\Lib\site-packages\django\urls\resolvers.py", line 831, in _reverse_with_prefix
    raise NoReverseMatch(msg)
django.urls.exceptions.NoReverseMatch: Reverse for 'export_contributions' not found. 'export_contributions' is not a valid view function or pattern name.
Not Found: /favicon.ico
Not Found: /favicon.ico
Not Found: /favicon.ico
Not Found: /favicon.ico
Not Found: /favicon.ico
Not Found: /favicon.ico
Not Found: /favicon.ico
Not Found: /favicon.ico
Not Found: /favicon.ico
Not Found: /favicon.ico
Not Found: /favicon.ico
Not Found: /favicon.ico
Forbidden (CSRF cookie not set.): /accounts/login/
Forbidden (CSRF cookie not set.): /accounts/login/
Forbidden (CSRF cookie not set.): /accounts/login/
Forbidden (CSRF cookie not set.): /accounts/login/
Not Found: /favicon.ico
Forbidden (CSRF cookie not set.): /accounts/login/
Not Found: /favicon.ico
Not Found: /favicon.ico
Forbidden (CSRF cookie not set.): /accounts/login/
Forbidden (CSRF cookie not set.): /accounts/login/
Forbidden (CSRF cookie not set.): /accounts/login/
Forbidden (CSRF cookie not set.): /accounts/login/
Forbidden (CSRF cookie not set.): /accounts/login/
Forbidden (CSRF cookie not set.): /accounts/login/
Forbidden (CSRF cookie not set.): /accounts/login/
Not Found: /favicon.ico
Internal Server Error: /request-benefit/
Traceback (most recent call last):
  File "C:\Users\IT MINISTRY\PycharmProjects\FWB\.venv\Lib\site-packages\django\core\handlers\exception.py", line 55, in inner
    response = get_response(request)
  File "C:\Users\IT MINISTRY\PycharmProjects\FWB\.venv\Lib\site-packages\django\core\handlers\base.py", line 197, in _get_response
    response = wrapped_callback(request, *callback_args, **callback_kwargs)
  File "C:\Users\IT MINISTRY\PycharmProjects\FWB\.venv\Lib\site-packages\django\contrib\auth\decorators.py", line 60, in _view_wrapper
    return view_func(request, *args, **kwargs)
  File "C:\Users\IT MINISTRY\PycharmProjects\FWB\fwb\contributions\views.py", line 604, in request_benefit
    return render(request, "contributions/request_benefit.html", {"form": form})
  File "C:\Users\IT MINISTRY\PycharmProjects\FWB\.venv\Lib\site-packages\django\shortcuts.py", line 25, in render
    content = loader.render_to_string(template_name, context, request, using=using)
  File "C:\Users\IT MINISTRY\PycharmProjects\FWB\.venv\Lib\site-packages\django\template\loader.py", line 61, in render_to_string
    template = get_template(template_name, using=using)
  File "C:\Users\IT MINISTRY\PycharmProjects\FWB\.venv\Lib\site-packages\django\template\loader.py", line 19, in get_template
    raise TemplateDoesNotExist(template_name, chain=chain)
django.template.exceptions.TemplateDoesNotExist: contributions/request_benefit.html
Not Found: /favicon.ico
Internal Server Error: /request-benefit/
Traceback (most recent call last):
  File "C:\Users\deedadey\AppData\Local\Programs\Python\Python312\Lib\site-packages\django\core\handlers\exception.py", line 55, in inner
    response = get_response(request)
               ^^^^^^^^^^^^^^^^^^^^^
  File "C:\Users\deedadey\AppData\Local\Programs\Python\Python312\Lib\site-packages\django\core\handlers\base.py", line 197, in _get_response
    response = wrapped_callback(request, *callback_args, **callback_kwargs)
               ^^^^^^^^^^^^^^^^^^^^^^^^^^^^^^^^^^^^^^^^^^^^^^^^^^^^^^^^^^^^
  File "C:\Users\deedadey\AppData\Local\Programs\Python\Python312\Lib\site-packages\django\contrib\auth\decorators.py", line 60, in _view_wrapper
    return view_func(request, *args, **kwargs)
           ^^^^^^^^^^^^^^^^^^^^^^^^^^^^^^^^^^^
  File "C:\Users\deedadey\PycharmProjects\FWB\fwb\contributions\views.py", line 604, in request_benefit
    return render(request, "contributions/request_benefit.html", {"form": form})
           ^^^^^^^^^^^^^^^^^^^^^^^^^^^^^^^^^^^^^^^^^^^^^^^^^^^^^^^^^^^^^^^^^^^^^
  File "C:\Users\deedadey\AppData\Local\Programs\Python\Python312\Lib\site-packages\django\shortcuts.py", line 25, in render
    content = loader.render_to_string(template_name, context, request, using=using)
              ^^^^^^^^^^^^^^^^^^^^^^^^^^^^^^^^^^^^^^^^^^^^^^^^^^^^^^^^^^^^^^^^^^^^^
  File "C:\Users\deedadey\AppData\Local\Programs\Python\Python312\Lib\site-packages\django\template\loader.py", line 61, in render_to_string
    template = get_template(template_name, using=using)
               ^^^^^^^^^^^^^^^^^^^^^^^^^^^^^^^^^^^^^^^^
  File "C:\Users\deedadey\AppData\Local\Programs\Python\Python312\Lib\site-packages\django\template\loader.py", line 19, in get_template
    raise TemplateDoesNotExist(template_name, chain=chain)
django.template.exceptions.TemplateDoesNotExist: contributions/request_benefit.html
Internal Server Error: /request-benefit/
Traceback (most recent call last):
  File "C:\Users\deedadey\AppData\Local\Programs\Python\Python312\Lib\site-packages\django\core\handlers\exception.py", line 55, in inner
    response = get_response(request)
               ^^^^^^^^^^^^^^^^^^^^^
  File "C:\Users\deedadey\AppData\Local\Programs\Python\Python312\Lib\site-packages\django\core\handlers\base.py", line 197, in _get_response
    response = wrapped_callback(request, *callback_args, **callback_kwargs)
               ^^^^^^^^^^^^^^^^^^^^^^^^^^^^^^^^^^^^^^^^^^^^^^^^^^^^^^^^^^^^
  File "C:\Users\deedadey\AppData\Local\Programs\Python\Python312\Lib\site-packages\django\contrib\auth\decorators.py", line 60, in _view_wrapper
    return view_func(request, *args, **kwargs)
           ^^^^^^^^^^^^^^^^^^^^^^^^^^^^^^^^^^^
  File "C:\Users\deedadey\PycharmProjects\FWB\fwb\contributions\views.py", line 604, in request_benefit
    return render(request, "contributions/request_benefit.html", {"form": form})
           ^^^^^^^^^^^^^^^^^^^^^^^^^^^^^^^^^^^^^^^^^^^^^^^^^^^^^^^^^^^^^^^^^^^^^
  File "C:\Users\deedadey\AppData\Local\Programs\Python\Python312\Lib\site-packages\django\shortcuts.py", line 25, in render
    content = loader.render_to_string(template_name, context, request, using=using)
              ^^^^^^^^^^^^^^^^^^^^^^^^^^^^^^^^^^^^^^^^^^^^^^^^^^^^^^^^^^^^^^^^^^^^^
  File "C:\Users\deedadey\AppData\Local\Programs\Python\Python312\Lib\site-packages\django\template\loader.py", line 61, in render_to_string
    template = get_template(template_name, using=using)
               ^^^^^^^^^^^^^^^^^^^^^^^^^^^^^^^^^^^^^^^^
  File "C:\Users\deedadey\AppData\Local\Programs\Python\Python312\Lib\site-packages\django\template\loader.py", line 19, in get_template
    raise TemplateDoesNotExist(template_name, chain=chain)
django.template.exceptions.TemplateDoesNotExist: contributions/request_benefit.html
Internal Server Error: /request-benefit/
Traceback (most recent call last):
  File "C:\Users\deedadey\AppData\Local\Programs\Python\Python312\Lib\site-packages\django\core\handlers\exception.py", line 55, in inner
    response = get_response(request)
               ^^^^^^^^^^^^^^^^^^^^^
  File "C:\Users\deedadey\AppData\Local\Programs\Python\Python312\Lib\site-packages\django\core\handlers\base.py", line 197, in _get_response
    response = wrapped_callback(request, *callback_args, **callback_kwargs)
               ^^^^^^^^^^^^^^^^^^^^^^^^^^^^^^^^^^^^^^^^^^^^^^^^^^^^^^^^^^^^
  File "C:\Users\deedadey\AppData\Local\Programs\Python\Python312\Lib\site-packages\django\contrib\auth\decorators.py", line 60, in _view_wrapper
    return view_func(request, *args, **kwargs)
           ^^^^^^^^^^^^^^^^^^^^^^^^^^^^^^^^^^^
  File "C:\Users\deedadey\PycharmProjects\FWB\fwb\contributions\views.py", line 604, in request_benefit
    return render(request, "contributions/request_benefit.html", {"form": form})
           ^^^^^^^^^^^^^^^^^^^^^^^^^^^^^^^^^^^^^^^^^^^^^^^^^^^^^^^^^^^^^^^^^^^^^
  File "C:\Users\deedadey\AppData\Local\Programs\Python\Python312\Lib\site-packages\django\shortcuts.py", line 25, in render
    content = loader.render_to_string(template_name, context, request, using=using)
              ^^^^^^^^^^^^^^^^^^^^^^^^^^^^^^^^^^^^^^^^^^^^^^^^^^^^^^^^^^^^^^^^^^^^^
  File "C:\Users\deedadey\AppData\Local\Programs\Python\Python312\Lib\site-packages\django\template\loader.py", line 61, in render_to_string
    template = get_template(template_name, using=using)
               ^^^^^^^^^^^^^^^^^^^^^^^^^^^^^^^^^^^^^^^^
  File "C:\Users\deedadey\AppData\Local\Programs\Python\Python312\Lib\site-packages\django\template\loader.py", line 19, in get_template
    raise TemplateDoesNotExist(template_name, chain=chain)
django.template.exceptions.TemplateDoesNotExist: contributions/request_benefit.html
Not Found: /favicon.ico
Internal Server Error: /request-benefit/
Traceback (most recent call last):
  File "C:\Users\deedadey\AppData\Local\Programs\Python\Python312\Lib\site-packages\django\core\handlers\exception.py", line 55, in inner
    response = get_response(request)
               ^^^^^^^^^^^^^^^^^^^^^
  File "C:\Users\deedadey\AppData\Local\Programs\Python\Python312\Lib\site-packages\django\core\handlers\base.py", line 197, in _get_response
    response = wrapped_callback(request, *callback_args, **callback_kwargs)
               ^^^^^^^^^^^^^^^^^^^^^^^^^^^^^^^^^^^^^^^^^^^^^^^^^^^^^^^^^^^^
  File "C:\Users\deedadey\AppData\Local\Programs\Python\Python312\Lib\site-packages\django\contrib\auth\decorators.py", line 60, in _view_wrapper
    return view_func(request, *args, **kwargs)
           ^^^^^^^^^^^^^^^^^^^^^^^^^^^^^^^^^^^
  File "C:\Users\deedadey\PycharmProjects\FWB\fwb\contributions\views.py", line 604, in request_benefit
    return render(request, "contributions/request_benefit.html", {"form": form})
           ^^^^^^^^^^^^^^^^^^^^^^^^^^^^^^^^^^^^^^^^^^^^^^^^^^^^^^^^^^^^^^^^^^^^^
  File "C:\Users\deedadey\AppData\Local\Programs\Python\Python312\Lib\site-packages\django\shortcuts.py", line 25, in render
    content = loader.render_to_string(template_name, context, request, using=using)
              ^^^^^^^^^^^^^^^^^^^^^^^^^^^^^^^^^^^^^^^^^^^^^^^^^^^^^^^^^^^^^^^^^^^^^
  File "C:\Users\deedadey\AppData\Local\Programs\Python\Python312\Lib\site-packages\django\template\loader.py", line 61, in render_to_string
    template = get_template(template_name, using=using)
               ^^^^^^^^^^^^^^^^^^^^^^^^^^^^^^^^^^^^^^^^
  File "C:\Users\deedadey\AppData\Local\Programs\Python\Python312\Lib\site-packages\django\template\loader.py", line 19, in get_template
    raise TemplateDoesNotExist(template_name, chain=chain)
django.template.exceptions.TemplateDoesNotExist: contributions/request_benefit.html
Internal Server Error: /request-benefit/
Traceback (most recent call last):
  File "C:\Users\deedadey\AppData\Local\Programs\Python\Python312\Lib\site-packages\django\template\defaulttags.py", line 1035, in find_library
    return parser.libraries[name]
           ~~~~~~~~~~~~~~~~^^^^^^
KeyError: 'crispy_forms_tags'

During handling of the above exception, another exception occurred:

Traceback (most recent call last):
  File "C:\Users\deedadey\AppData\Local\Programs\Python\Python312\Lib\site-packages\django\core\handlers\exception.py", line 55, in inner
    response = get_response(request)
               ^^^^^^^^^^^^^^^^^^^^^
  File "C:\Users\deedadey\AppData\Local\Programs\Python\Python312\Lib\site-packages\django\core\handlers\base.py", line 197, in _get_response
    response = wrapped_callback(request, *callback_args, **callback_kwargs)
               ^^^^^^^^^^^^^^^^^^^^^^^^^^^^^^^^^^^^^^^^^^^^^^^^^^^^^^^^^^^^
  File "C:\Users\deedadey\AppData\Local\Programs\Python\Python312\Lib\site-packages\django\contrib\auth\decorators.py", line 60, in _view_wrapper
    return view_func(request, *args, **kwargs)
           ^^^^^^^^^^^^^^^^^^^^^^^^^^^^^^^^^^^
  File "C:\Users\deedadey\PycharmProjects\FWB\fwb\contributions\views.py", line 604, in request_benefit
    return render(request, "contributions/request_benefit.html", {"form": form})
           ^^^^^^^^^^^^^^^^^^^^^^^^^^^^^^^^^^^^^^^^^^^^^^^^^^^^^^^^^^^^^^^^^^^^^
  File "C:\Users\deedadey\AppData\Local\Programs\Python\Python312\Lib\site-packages\django\shortcuts.py", line 25, in render
    content = loader.render_to_string(template_name, context, request, using=using)
              ^^^^^^^^^^^^^^^^^^^^^^^^^^^^^^^^^^^^^^^^^^^^^^^^^^^^^^^^^^^^^^^^^^^^^
  File "C:\Users\deedadey\AppData\Local\Programs\Python\Python312\Lib\site-packages\django\template\loader.py", line 61, in render_to_string
    template = get_template(template_name, using=using)
               ^^^^^^^^^^^^^^^^^^^^^^^^^^^^^^^^^^^^^^^^
  File "C:\Users\deedadey\AppData\Local\Programs\Python\Python312\Lib\site-packages\django\template\loader.py", line 15, in get_template
    return engine.get_template(template_name)
           ^^^^^^^^^^^^^^^^^^^^^^^^^^^^^^^^^^
  File "C:\Users\deedadey\AppData\Local\Programs\Python\Python312\Lib\site-packages\django\template\backends\django.py", line 79, in get_template
    return Template(self.engine.get_template(template_name), self)
                    ^^^^^^^^^^^^^^^^^^^^^^^^^^^^^^^^^^^^^^^
  File "C:\Users\deedadey\AppData\Local\Programs\Python\Python312\Lib\site-packages\django\template\engine.py", line 177, in get_template
    template, origin = self.find_template(template_name)
                       ^^^^^^^^^^^^^^^^^^^^^^^^^^^^^^^^^
  File "C:\Users\deedadey\AppData\Local\Programs\Python\Python312\Lib\site-packages\django\template\engine.py", line 159, in find_template
    template = loader.get_template(name, skip=skip)
               ^^^^^^^^^^^^^^^^^^^^^^^^^^^^^^^^^^^^
  File "C:\Users\deedadey\AppData\Local\Programs\Python\Python312\Lib\site-packages\django\template\loaders\cached.py", line 57, in get_template
    template = super().get_template(template_name, skip)
               ^^^^^^^^^^^^^^^^^^^^^^^^^^^^^^^^^^^^^^^^^
  File "C:\Users\deedadey\AppData\Local\Programs\Python\Python312\Lib\site-packages\django\template\loaders\base.py", line 28, in get_template
    return Template(
           ^^^^^^^^^
  File "C:\Users\deedadey\AppData\Local\Programs\Python\Python312\Lib\site-packages\django\template\base.py", line 154, in __init__
    self.nodelist = self.compile_nodelist()
                    ^^^^^^^^^^^^^^^^^^^^^^^
  File "C:\Users\deedadey\AppData\Local\Programs\Python\Python312\Lib\site-packages\django\template\base.py", line 196, in compile_nodelist
    nodelist = parser.parse()
               ^^^^^^^^^^^^^^
  File "C:\Users\deedadey\AppData\Local\Programs\Python\Python312\Lib\site-packages\django\template\base.py", line 518, in parse
    raise self.error(token, e)
  File "C:\Users\deedadey\AppData\Local\Programs\Python\Python312\Lib\site-packages\django\template\base.py", line 516, in parse
    compiled_result = compile_func(self, token)
                      ^^^^^^^^^^^^^^^^^^^^^^^^^
  File "C:\Users\deedadey\AppData\Local\Programs\Python\Python312\Lib\site-packages\django\template\loader_tags.py", line 295, in do_extends
    nodelist = parser.parse()
               ^^^^^^^^^^^^^^
  File "C:\Users\deedadey\AppData\Local\Programs\Python\Python312\Lib\site-packages\django\template\base.py", line 518, in parse
    raise self.error(token, e)
  File "C:\Users\deedadey\AppData\Local\Programs\Python\Python312\Lib\site-packages\django\template\base.py", line 516, in parse
    compiled_result = compile_func(self, token)
                      ^^^^^^^^^^^^^^^^^^^^^^^^^
  File "C:\Users\deedadey\AppData\Local\Programs\Python\Python312\Lib\site-packages\django\template\defaulttags.py", line 1097, in load
    lib = find_library(parser, name)
          ^^^^^^^^^^^^^^^^^^^^^^^^^^
  File "C:\Users\deedadey\AppData\Local\Programs\Python\Python312\Lib\site-packages\django\template\defaulttags.py", line 1037, in find_library
    raise TemplateSyntaxError(
django.template.exceptions.TemplateSyntaxError: 'crispy_forms_tags' is not a registered tag library. Must be one of:
admin_list
admin_modify
admin_urls
cache
custom_filters
i18n
l10n
log
static
tz
Internal Server Error: /request-benefit/
Traceback (most recent call last):
  File "C:\Users\deedadey\AppData\Local\Programs\Python\Python312\Lib\site-packages\django\core\handlers\exception.py", line 55, in inner
    response = get_response(request)
               ^^^^^^^^^^^^^^^^^^^^^
  File "C:\Users\deedadey\AppData\Local\Programs\Python\Python312\Lib\site-packages\django\core\handlers\base.py", line 197, in _get_response
    response = wrapped_callback(request, *callback_args, **callback_kwargs)
               ^^^^^^^^^^^^^^^^^^^^^^^^^^^^^^^^^^^^^^^^^^^^^^^^^^^^^^^^^^^^
  File "C:\Users\deedadey\AppData\Local\Programs\Python\Python312\Lib\site-packages\django\contrib\auth\decorators.py", line 60, in _view_wrapper
    return view_func(request, *args, **kwargs)
           ^^^^^^^^^^^^^^^^^^^^^^^^^^^^^^^^^^^
  File "C:\Users\deedadey\PycharmProjects\FWB\fwb\contributions\views.py", line 594, in request_benefit
    if form.is_valid():
       ^^^^^^^^^^^^^^^
  File "C:\Users\deedadey\AppData\Local\Programs\Python\Python312\Lib\site-packages\django\forms\forms.py", line 197, in is_valid
    return self.is_bound and not self.errors
                                 ^^^^^^^^^^^
  File "C:\Users\deedadey\AppData\Local\Programs\Python\Python312\Lib\site-packages\django\forms\forms.py", line 192, in errors
    self.full_clean()
  File "C:\Users\deedadey\AppData\Local\Programs\Python\Python312\Lib\site-packages\django\forms\forms.py", line 327, in full_clean
    self._post_clean()
  File "C:\Users\deedadey\AppData\Local\Programs\Python\Python312\Lib\site-packages\django\forms\models.py", line 498, in _post_clean
    self.instance.full_clean(exclude=exclude, validate_unique=False)
  File "C:\Users\deedadey\AppData\Local\Programs\Python\Python312\Lib\site-packages\django\db\models\base.py", line 1626, in full_clean
    self.clean()
  File "C:\Users\deedadey\PycharmProjects\FWB\fwb\contributions\models.py", line 165, in clean
    if self.amount_requested <= Decimal("0"):
       ^^^^^^^^^^^^^^^^^^^^^^^^^^^^^^^^^^^^^
TypeError: '<=' not supported between instances of 'NoneType' and 'decimal.Decimal'
Not Found: /accounting_dashboard
Not Found: /favicon.ico
Not Found: /favicon.ico
Internal Server Error: /request-benefit/
Traceback (most recent call last):
  File "C:\Users\IT MINISTRY\PycharmProjects\FWB\.venv\Lib\site-packages\django\forms\models.py", line 498, in _post_clean
    self.instance.full_clean(exclude=exclude, validate_unique=False)
    ~~~~~~~~~~~~~~~~~~~~~~~~^^^^^^^^^^^^^^^^^^^^^^^^^^^^^^^^^^^^^^^^
  File "C:\Users\IT MINISTRY\PycharmProjects\FWB\.venv\Lib\site-packages\django\db\models\base.py", line 1651, in full_clean
    raise ValidationError(errors)
django.core.exceptions.ValidationError: {'amount_requested': ['This field is required.']}

During handling of the above exception, another exception occurred:

Traceback (most recent call last):
  File "C:\Users\IT MINISTRY\PycharmProjects\FWB\.venv\Lib\site-packages\django\core\handlers\exception.py", line 55, in inner
    response = get_response(request)
  File "C:\Users\IT MINISTRY\PycharmProjects\FWB\.venv\Lib\site-packages\django\core\handlers\base.py", line 197, in _get_response
    response = wrapped_callback(request, *callback_args, **callback_kwargs)
  File "C:\Users\IT MINISTRY\PycharmProjects\FWB\.venv\Lib\site-packages\django\contrib\auth\decorators.py", line 60, in _view_wrapper
    return view_func(request, *args, **kwargs)
  File "C:\Users\IT MINISTRY\PycharmProjects\FWB\fwb\contributions\views.py", line 596, in request_benefit
    if form.is_valid():
       ~~~~~~~~~~~~~^^
  File "C:\Users\IT MINISTRY\PycharmProjects\FWB\.venv\Lib\site-packages\django\forms\forms.py", line 197, in is_valid
    return self.is_bound and not self.errors
                                 ^^^^^^^^^^^
  File "C:\Users\IT MINISTRY\PycharmProjects\FWB\.venv\Lib\site-packages\django\forms\forms.py", line 192, in errors
    self.full_clean()
    ~~~~~~~~~~~~~~~^^
  File "C:\Users\IT MINISTRY\PycharmProjects\FWB\.venv\Lib\site-packages\django\forms\forms.py", line 327, in full_clean
    self._post_clean()
    ~~~~~~~~~~~~~~~~^^
  File "C:\Users\IT MINISTRY\PycharmProjects\FWB\.venv\Lib\site-packages\django\forms\models.py", line 500, in _post_clean
    self._update_errors(e)
    ~~~~~~~~~~~~~~~~~~~^^^
  File "C:\Users\IT MINISTRY\PycharmProjects\FWB\.venv\Lib\site-packages\django\forms\models.py", line 472, in _update_errors
    self.add_error(None, errors)
    ~~~~~~~~~~~~~~^^^^^^^^^^^^^^
  File "C:\Users\IT MINISTRY\PycharmProjects\FWB\.venv\Lib\site-packages\django\forms\forms.py", line 292, in add_error
    raise ValueError(
    ...<2 lines>...
    )
ValueError: 'BenefitRequestForm' has no field named 'amount_requested'.
Internal Server Error: /request-benefit/
Traceback (most recent call last):
  File "C:\Users\IT MINISTRY\PycharmProjects\FWB\.venv\Lib\site-packages\django\forms\models.py", line 498, in _post_clean
    self.instance.full_clean(exclude=exclude, validate_unique=False)
    ~~~~~~~~~~~~~~~~~~~~~~~~^^^^^^^^^^^^^^^^^^^^^^^^^^^^^^^^^^^^^^^^
  File "C:\Users\IT MINISTRY\PycharmProjects\FWB\.venv\Lib\site-packages\django\db\models\base.py", line 1651, in full_clean
    raise ValidationError(errors)
django.core.exceptions.ValidationError: {'amount_requested': ['This field is required.']}

During handling of the above exception, another exception occurred:

Traceback (most recent call last):
  File "C:\Users\IT MINISTRY\PycharmProjects\FWB\.venv\Lib\site-packages\django\core\handlers\exception.py", line 55, in inner
    response = get_response(request)
  File "C:\Users\IT MINISTRY\PycharmProjects\FWB\.venv\Lib\site-packages\django\core\handlers\base.py", line 197, in _get_response
    response = wrapped_callback(request, *callback_args, **callback_kwargs)
  File "C:\Users\IT MINISTRY\PycharmProjects\FWB\.venv\Lib\site-packages\django\contrib\auth\decorators.py", line 60, in _view_wrapper
    return view_func(request, *args, **kwargs)
  File "C:\Users\IT MINISTRY\PycharmProjects\FWB\fwb\contributions\views.py", line 596, in request_benefit
    if form.is_valid():
       ~~~~~~~~~~~~~^^
  File "C:\Users\IT MINISTRY\PycharmProjects\FWB\.venv\Lib\site-packages\django\forms\forms.py", line 197, in is_valid
    return self.is_bound and not self.errors
                                 ^^^^^^^^^^^
  File "C:\Users\IT MINISTRY\PycharmProjects\FWB\.venv\Lib\site-packages\django\forms\forms.py", line 192, in errors
    self.full_clean()
    ~~~~~~~~~~~~~~~^^
  File "C:\Users\IT MINISTRY\PycharmProjects\FWB\.venv\Lib\site-packages\django\forms\forms.py", line 327, in full_clean
    self._post_clean()
    ~~~~~~~~~~~~~~~~^^
  File "C:\Users\IT MINISTRY\PycharmProjects\FWB\.venv\Lib\site-packages\django\forms\models.py", line 500, in _post_clean
    self._update_errors(e)
    ~~~~~~~~~~~~~~~~~~~^^^
  File "C:\Users\IT MINISTRY\PycharmProjects\FWB\.venv\Lib\site-packages\django\forms\models.py", line 472, in _update_errors
    self.add_error(None, errors)
    ~~~~~~~~~~~~~~^^^^^^^^^^^^^^
  File "C:\Users\IT MINISTRY\PycharmProjects\FWB\.venv\Lib\site-packages\django\forms\forms.py", line 292, in add_error
    raise ValueError(
    ...<2 lines>...
    )
ValueError: 'BenefitRequestForm' has no field named 'amount_requested'.
